Workbook

Sheet GARA
A1: STAZIONE APPALTANTE | B1: SACE S.p.A.
A2: DENOMINAZIONE | B2: Affidamento del servizio di application maintenance, evoluzione e gestione dati su framework Salesforce
A3: CIG | B3: BD26C6E412
A4: CUP
A5: BASE D'ASTA | B5: 695200
A6: IMPORTO COMPLESSIVO COMPRENSIVO DI RINNOVI | B6: 1390400
A7: DURATA | B7: 24 + 24 (Rinnovo Opzionale)
A8: SCADENZA | B8: 2026-10-30T12:00:00Z

Sheet PUNTEGGIO TECNICO
B1: C1 | C1: C2 | D1: C3 | E1: C4 | F1: C5A | G1: C5B | H1: C5C | I1: PT | J1: PT RIP | L1: CODICE | M1: CRITERIO | N1: PUNTEGGIO | O1: TIPOLOGIA
A2: LINKS | B2: B | C2: O | D2: B | E2: O | F2: 7 | G2: B | H2: O | I2: =SUM(B14:H14) -> #N/A | J2: =IF($N$13="T",I2/MAX($I$2:$I$11)*$N$9,SUM(B26:H26)) -> #N/A | L2: C1 | M2: Presentazione aziendale e referenze | N2: 10 | O2: D
A3: ALTRO 1 | B3: B | C3: O | D3: B | E3: D | F3: 5 | G3: O | H3: B | I3: =SUM(B15:H15) -> #N/A | J3: =IF($N$13="T",I3/MAX($I$2:$I$11)*$N$9,SUM(B27:H27)) -> #N/A | L3: C2.1 | M3: Organizzazione del servizio offerto | N3: 5 | O3: D
A4: ALTRO 2 | B4: D | C4: D | D4: B | E4: D | F4: 7 | G4: B | H4: D | I4: =SUM(B16:H16) -> #N/A | J4: =IF($N$13="T",I4/MAX($I$2:$I$11)*$N$9,SUM(B28:H28)) -> #N/A | L4: C2.2 | M4: Affiancamento e trasferimento know-how | N4: 5 | O4: D
A5: ALTRO 3 | B5: S | C5: B | D5: B | E5: O | F5: 5 | G5: B | H5: B | I5: =SUM(B17:H17) -> #N/A | J5: =IF($N$13="T",I5/MAX($I$2:$I$11)*$N$9,SUM(B29:H29)) -> #N/A | L5: C3 | M5: Qualità delle singole risorse componenti il team | N5: 25 | O5: D
A6: ALTRO 4 | B6: D | C6: B | D6: B | E6: O | F6: 5 | G6: O | H6: B | I6: =SUM(B18:H18) -> #N/A | J6: =IF($N$13="T",I6/MAX($I$2:$I$11)*$N$9,SUM(B30:H30)) -> #N/A | L6: C4 | M6: Proposte di livelli di servizio migliorativi | N6: 24 | O6: D
A7: ALTRO 5 | B7: D | C7: B | D7: B | E7: O | F7: 5 | G7: B | H7: B | I7: =SUM(B19:H19) -> #N/A | J7: =IF($N$13="T",I7/MAX($I$2:$I$11)*$N$9,SUM(B31:H31)) -> #N/A | L7: C5 | M7: Misure a tutela della diversità e pari opportunità - ISO 30415:2021 o UNI PDR 125:2022 | N7: 1 | O7: T
A8: ALTRO 6 | B8: O | C8: B | D8: B | E8: S | F8: 5 | G8: B | H8: D | I8: =SUM(B20:H20) -> #N/A | J8: =IF($N$13="T",I8/MAX($I$2:$I$11)*$N$9,SUM(B32:H32)) -> #N/A | L8: C6 | M8: Certificazioni ISO 27001, ISO 27017:2015, ISO 20000-1:2018 | N8: 10 | O8: T
A9: ALTRO 7 | B9: D | C9: B | D9: B | E9: O | F9: 5 | G9: O | H9: D | I9: =SUM(B21:H21) -> #N/A | J9: =IF($N$13="T",I9/MAX($I$2:$I$11)*$N$9,SUM(B33:H33)) -> #N/A | M9: TOT. PUNTEGGIO TECNICO | N9: =SUM(N2:N8) -> 80
A10: ALTRO 8 | B10: O | C10: S | D10: B | E10: O | F10: 5 | G10: S | H10: B | I10: =SUM(B22:H22) -> #N/A | J10: =IF($N$13="T",I10/MAX($I$2:$I$11)*$N$9,SUM(B34:H34)) -> #N/A | M10: DI CUI DISCREZIONALE … | N10: =SUMIF(O2:O8,"D",N2:N8) -> 69
A11: ALTRO 9 | B11: D | C11: O | D11: S | E11: S | F11: 7 | G11: O | H11: B | I11: =SUM(B23:H23) -> #N/A | J11: =IF($N$13="T",I11/MAX($I$2:$I$11)*$N$9,SUM(B35:H35)) -> #N/A | M11: DI CUI TABELLARE … | N11: =SUMIF(O2:O8,"T",N2:N8) -> 11
M12: PUNTEGGIO TECNICO MINIMO
B13: C1 | C13: C2 | D13: C3 | E13: C4 | F13: C5A | G13: C5B | H13: C5C | M13: RIPARAMETRAZIONE PARZIALE O TOTALE | N13: P
A14: =A2 -> LINKS | B14: {=IF(ISNUMBER(B2),B26B2,_xlfn.XLOOKUP(B$13,$L$2:$L$8,$N$2:$N$8)*_xlfn.XLOOKUP(B2,$O$15:$O$20,$N$15:$N$20))} -> 8 | C14: =IF(ISNUMBER(C2),C2,_xlfn.XLOOKUP(C$13,$L$2:$L$8,$N$2:$N$8)*_xlfn.XLOOKUP(C2,$O$15:$O$20,$N$15:$N$20)) -> #N/A | D14: =IF(ISNUMBER(D2),D2,_xlfn.XLOOKUP(D$13,$L$2:$L$8,$N$2:$N$8)*_xlfn.XLOOKUP(D2,$O$15:$O$20,$N$15:$N$20)) -> 20 | E14: =IF(ISNUMBER(E2),E2,_xlfn.XLOOKUP(E$13,$L$2:$L$8,$N$2:$N$8)*_xlfn.XLOOKUP(E2,$O$15:$O$20,$N$15:$N$20)) -> 24 | F14: =IF(ISNUMBER(F2),F2,_xlfn.XLOOKUP(F$13,$L$2:$L$8,$N$2:$N$8)*_xlfn.XLOOKUP(F2,$O$15:$O$20,$N$15:$N$20)) -> 7 | G14: =IF(ISNUMBER(G2),G2,_xlfn.XLOOKUP(G$13,$L$2:$L$8,$N$2:$N$8)*_xlfn.XLOOKUP(G2,$O$15:$O$20,$N$15:$N$20)) -> #N/A | H14: =IF(ISNUMBER(H2),H2,_xlfn.XLOOKUP(H$13,$L$2:$L$8,$N$2:$N$8)*_xlfn.XLOOKUP(H2,$O$15:$O$20,$N$15:$N$20)) -> #N/A | M14: MODALITA' D
A15: =A3 -> ALTRO 1 | B15: =IF(ISNUMBER(B3),B3,_xlfn.XLOOKUP(B$13,$L$2:$L$8,$N$2:$N$8)*_xlfn.XLOOKUP(B3,$O$15:$O$20,$N$15:$N$20)) -> 8 | C15: =IF(ISNUMBER(C3),C3,_xlfn.XLOOKUP(C$13,$L$2:$L$8,$N$2:$N$8)*_xlfn.XLOOKUP(C3,$O$15:$O$20,$N$15:$N$20)) -> #N/A | D15: =IF(ISNUMBER(D3),D3,_xlfn.XLOOKUP(D$13,$L$2:$L$8,$N$2:$N$8)*_xlfn.XLOOKUP(D3,$O$15:$O$20,$N$15:$N$20)) -> 20 | E15: =IF(ISNUMBER(E3),E3,_xlfn.XLOOKUP(E$13,$L$2:$L$8,$N$2:$N$8)*_xlfn.XLOOKUP(E3,$O$15:$O$20,$N$15:$N$20)) -> 14.4 | F15: =IF(ISNUMBER(F3),F3,_xlfn.XLOOKUP(F$13,$L$2:$L$8,$N$2:$N$8)*_xlfn.XLOOKUP(F3,$O$15:$O$20,$N$15:$N$20)) -> 5 | G15: =IF(ISNUMBER(G3),G3,_xlfn.XLOOKUP(G$13,$L$2:$L$8,$N$2:$N$8)*_xlfn.XLOOKUP(G3,$O$15:$O$20,$N$15:$N$20)) -> #N/A | H15: =IF(ISNUMBER(H3),H3,_xlfn.XLOOKUP(H$13,$L$2:$L$8,$N$2:$N$8)*_xlfn.XLOOKUP(H3,$O$15:$O$20,$N$15:$N$20)) -> #N/A | M15: Ottimo | N15: 1 | O15: O
A16: =A4 -> ALTRO 2 | B16: =IF(ISNUMBER(B4),B4,_xlfn.XLOOKUP(B$13,$L$2:$L$8,$N$2:$N$8)*_xlfn.XLOOKUP(B4,$O$15:$O$20,$N$15:$N$20)) -> 6 | C16: =IF(ISNUMBER(C4),C4,_xlfn.XLOOKUP(C$13,$L$2:$L$8,$N$2:$N$8)*_xlfn.XLOOKUP(C4,$O$15:$O$20,$N$15:$N$20)) -> #N/A | D16: =IF(ISNUMBER(D4),D4,_xlfn.XLOOKUP(D$13,$L$2:$L$8,$N$2:$N$8)*_xlfn.XLOOKUP(D4,$O$15:$O$20,$N$15:$N$20)) -> 20 | E16: =IF(ISNUMBER(E4),E4,_xlfn.XLOOKUP(E$13,$L$2:$L$8,$N$2:$N$8)*_xlfn.XLOOKUP(E4,$O$15:$O$20,$N$15:$N$20)) -> 14.4 | F16: =IF(ISNUMBER(F4),F4,_xlfn.XLOOKUP(F$13,$L$2:$L$8,$N$2:$N$8)*_xlfn.XLOOKUP(F4,$O$15:$O$20,$N$15:$N$20)) -> 7 | G16: =IF(ISNUMBER(G4),G4,_xlfn.XLOOKUP(G$13,$L$2:$L$8,$N$2:$N$8)*_xlfn.XLOOKUP(G4,$O$15:$O$20,$N$15:$N$20)) -> #N/A | H16: =IF(ISNUMBER(H4),H4,_xlfn.XLOOKUP(H$13,$L$2:$L$8,$N$2:$N$8)*_xlfn.XLOOKUP(H4,$O$15:$O$20,$N$15:$N$20)) -> #N/A | M16: Buono | N16: 0.8 | O16: B
A17: =A5 -> ALTRO 3 | B17: =IF(ISNUMBER(B5),B5,_xlfn.XLOOKUP(B$13,$L$2:$L$8,$N$2:$N$8)*_xlfn.XLOOKUP(B5,$O$15:$O$20,$N$15:$N$20)) -> 4 | C17: =IF(ISNUMBER(C5),C5,_xlfn.XLOOKUP(C$13,$L$2:$L$8,$N$2:$N$8)*_xlfn.XLOOKUP(C5,$O$15:$O$20,$N$15:$N$20)) -> #N/A | D17: =IF(ISNUMBER(D5),D5,_xlfn.XLOOKUP(D$13,$L$2:$L$8,$N$2:$N$8)*_xlfn.XLOOKUP(D5,$O$15:$O$20,$N$15:$N$20)) -> 20 | E17: =IF(ISNUMBER(E5),E5,_xlfn.XLOOKUP(E$13,$L$2:$L$8,$N$2:$N$8)*_xlfn.XLOOKUP(E5,$O$15:$O$20,$N$15:$N$20)) -> 24 | F17: =IF(ISNUMBER(F5),F5,_xlfn.XLOOKUP(F$13,$L$2:$L$8,$N$2:$N$8)*_xlfn.XLOOKUP(F5,$O$15:$O$20,$N$15:$N$20)) -> 5 | G17: =IF(ISNUMBER(G5),G5,_xlfn.XLOOKUP(G$13,$L$2:$L$8,$N$2:$N$8)*_xlfn.XLOOKUP(G5,$O$15:$O$20,$N$15:$N$20)) -> #N/A | H17: =IF(ISNUMBER(H5),H5,_xlfn.XLOOKUP(H$13,$L$2:$L$8,$N$2:$N$8)*_xlfn.XLOOKUP(H5,$O$15:$O$20,$N$15:$N$20)) -> #N/A | M17: Discreto | N17: 0.6 | O17: D
A18: =A6 -> ALTRO 4 | B18: =IF(ISNUMBER(B6),B6,_xlfn.XLOOKUP(B$13,$L$2:$L$8,$N$2:$N$8)*_xlfn.XLOOKUP(B6,$O$15:$O$20,$N$15:$N$20)) -> 6 | C18: =IF(ISNUMBER(C6),C6,_xlfn.XLOOKUP(C$13,$L$2:$L$8,$N$2:$N$8)*_xlfn.XLOOKUP(C6,$O$15:$O$20,$N$15:$N$20)) -> #N/A | D18: =IF(ISNUMBER(D6),D6,_xlfn.XLOOKUP(D$13,$L$2:$L$8,$N$2:$N$8)*_xlfn.XLOOKUP(D6,$O$15:$O$20,$N$15:$N$20)) -> 20 | E18: =IF(ISNUMBER(E6),E6,_xlfn.XLOOKUP(E$13,$L$2:$L$8,$N$2:$N$8)*_xlfn.XLOOKUP(E6,$O$15:$O$20,$N$15:$N$20)) -> 24 | F18: =IF(ISNUMBER(F6),F6,_xlfn.XLOOKUP(F$13,$L$2:$L$8,$N$2:$N$8)*_xlfn.XLOOKUP(F6,$O$15:$O$20,$N$15:$N$20)) -> 5 | G18: =IF(ISNUMBER(G6),G6,_xlfn.XLOOKUP(G$13,$L$2:$L$8,$N$2:$N$8)*_xlfn.XLOOKUP(G6,$O$15:$O$20,$N$15:$N$20)) -> #N/A | H18: =IF(ISNUMBER(H6),H6,_xlfn.XLOOKUP(H$13,$L$2:$L$8,$N$2:$N$8)*_xlfn.XLOOKUP(H6,$O$15:$O$20,$N$15:$N$20)) -> #N/A | M18: Sufficiente | N18: 0.4 | O18: S
A19: =A7 -> ALTRO 5 | B19: =IF(ISNUMBER(B7),B7,_xlfn.XLOOKUP(B$13,$L$2:$L$8,$N$2:$N$8)*_xlfn.XLOOKUP(B7,$O$15:$O$20,$N$15:$N$20)) -> 6 | C19: =IF(ISNUMBER(C7),C7,_xlfn.XLOOKUP(C$13,$L$2:$L$8,$N$2:$N$8)*_xlfn.XLOOKUP(C7,$O$15:$O$20,$N$15:$N$20)) -> #N/A | D19: =IF(ISNUMBER(D7),D7,_xlfn.XLOOKUP(D$13,$L$2:$L$8,$N$2:$N$8)*_xlfn.XLOOKUP(D7,$O$15:$O$20,$N$15:$N$20)) -> 20 | E19: =IF(ISNUMBER(E7),E7,_xlfn.XLOOKUP(E$13,$L$2:$L$8,$N$2:$N$8)*_xlfn.XLOOKUP(E7,$O$15:$O$20,$N$15:$N$20)) -> 24 | F19: =IF(ISNUMBER(F7),F7,_xlfn.XLOOKUP(F$13,$L$2:$L$8,$N$2:$N$8)*_xlfn.XLOOKUP(F7,$O$15:$O$20,$N$15:$N$20)) -> 5 | G19: =IF(ISNUMBER(G7),G7,_xlfn.XLOOKUP(G$13,$L$2:$L$8,$N$2:$N$8)*_xlfn.XLOOKUP(G7,$O$15:$O$20,$N$15:$N$20)) -> #N/A | H19: =IF(ISNUMBER(H7),H7,_xlfn.XLOOKUP(H$13,$L$2:$L$8,$N$2:$N$8)*_xlfn.XLOOKUP(H7,$O$15:$O$20,$N$15:$N$20)) -> #N/A | M19: Scarso | N19: 0.2 | O19: SC
A20: =A8 -> ALTRO 6 | B20: =IF(ISNUMBER(B8),B8,_xlfn.XLOOKUP(B$13,$L$2:$L$8,$N$2:$N$8)*_xlfn.XLOOKUP(B8,$O$15:$O$20,$N$15:$N$20)) -> 10 | C20: =IF(ISNUMBER(C8),C8,_xlfn.XLOOKUP(C$13,$L$2:$L$8,$N$2:$N$8)*_xlfn.XLOOKUP(C8,$O$15:$O$20,$N$15:$N$20)) -> #N/A | D20: =IF(ISNUMBER(D8),D8,_xlfn.XLOOKUP(D$13,$L$2:$L$8,$N$2:$N$8)*_xlfn.XLOOKUP(D8,$O$15:$O$20,$N$15:$N$20)) -> 20 | E20: =IF(ISNUMBER(E8),E8,_xlfn.XLOOKUP(E$13,$L$2:$L$8,$N$2:$N$8)*_xlfn.XLOOKUP(E8,$O$15:$O$20,$N$15:$N$20)) -> 9.6 | F20: =IF(ISNUMBER(F8),F8,_xlfn.XLOOKUP(F$13,$L$2:$L$8,$N$2:$N$8)*_xlfn.XLOOKUP(F8,$O$15:$O$20,$N$15:$N$20)) -> 5 | G20: =IF(ISNUMBER(G8),G8,_xlfn.XLOOKUP(G$13,$L$2:$L$8,$N$2:$N$8)*_xlfn.XLOOKUP(G8,$O$15:$O$20,$N$15:$N$20)) -> #N/A | H20: =IF(ISNUMBER(H8),H8,_xlfn.XLOOKUP(H$13,$L$2:$L$8,$N$2:$N$8)*_xlfn.XLOOKUP(H8,$O$15:$O$20,$N$15:$N$20)) -> #N/A | M20: Insufficiente | N20: 0 | O20: I
A21: =A9 -> ALTRO 7 | B21: =IF(ISNUMBER(B9),B9,_xlfn.XLOOKUP(B$13,$L$2:$L$8,$N$2:$N$8)*_xlfn.XLOOKUP(B9,$O$15:$O$20,$N$15:$N$20)) -> 6 | C21: =IF(ISNUMBER(C9),C9,_xlfn.XLOOKUP(C$13,$L$2:$L$8,$N$2:$N$8)*_xlfn.XLOOKUP(C9,$O$15:$O$20,$N$15:$N$20)) -> #N/A | D21: =IF(ISNUMBER(D9),D9,_xlfn.XLOOKUP(D$13,$L$2:$L$8,$N$2:$N$8)*_xlfn.XLOOKUP(D9,$O$15:$O$20,$N$15:$N$20)) -> 20 | E21: =IF(ISNUMBER(E9),E9,_xlfn.XLOOKUP(E$13,$L$2:$L$8,$N$2:$N$8)*_xlfn.XLOOKUP(E9,$O$15:$O$20,$N$15:$N$20)) -> 24 | F21: =IF(ISNUMBER(F9),F9,_xlfn.XLOOKUP(F$13,$L$2:$L$8,$N$2:$N$8)*_xlfn.XLOOKUP(F9,$O$15:$O$20,$N$15:$N$20)) -> 5 | G21: =IF(ISNUMBER(G9),G9,_xlfn.XLOOKUP(G$13,$L$2:$L$8,$N$2:$N$8)*_xlfn.XLOOKUP(G9,$O$15:$O$20,$N$15:$N$20)) -> #N/A | H21: =IF(ISNUMBER(H9),H9,_xlfn.XLOOKUP(H$13,$L$2:$L$8,$N$2:$N$8)*_xlfn.XLOOKUP(H9,$O$15:$O$20,$N$15:$N$20)) -> #N/A
A22: =A10 -> ALTRO 8 | B22: =IF(ISNUMBER(B10),B10,_xlfn.XLOOKUP(B$13,$L$2:$L$8,$N$2:$N$8)*_xlfn.XLOOKUP(B10,$O$15:$O$20,$N$15:$N$20)) -> 10 | C22: =IF(ISNUMBER(C10),C10,_xlfn.XLOOKUP(C$13,$L$2:$L$8,$N$2:$N$8)*_xlfn.XLOOKUP(C10,$O$15:$O$20,$N$15:$N$20)) -> #N/A | D22: =IF(ISNUMBER(D10),D10,_xlfn.XLOOKUP(D$13,$L$2:$L$8,$N$2:$N$8)*_xlfn.XLOOKUP(D10,$O$15:$O$20,$N$15:$N$20)) -> 20 | E22: =IF(ISNUMBER(E10),E10,_xlfn.XLOOKUP(E$13,$L$2:$L$8,$N$2:$N$8)*_xlfn.XLOOKUP(E10,$O$15:$O$20,$N$15:$N$20)) -> 24 | F22: =IF(ISNUMBER(F10),F10,_xlfn.XLOOKUP(F$13,$L$2:$L$8,$N$2:$N$8)*_xlfn.XLOOKUP(F10,$O$15:$O$20,$N$15:$N$20)) -> 5 | G22: =IF(ISNUMBER(G10),G10,_xlfn.XLOOKUP(G$13,$L$2:$L$8,$N$2:$N$8)*_xlfn.XLOOKUP(G10,$O$15:$O$20,$N$15:$N$20)) -> #N/A | H22: =IF(ISNUMBER(H10),H10,_xlfn.XLOOKUP(H$13,$L$2:$L$8,$N$2:$N$8)*_xlfn.XLOOKUP(H10,$O$15:$O$20,$N$15:$N$20)) -> #N/A
A23: =A11 -> ALTRO 9 | B23: =IF(ISNUMBER(B11),B11,_xlfn.XLOOKUP(B$13,$L$2:$L$8,$N$2:$N$8)*_xlfn.XLOOKUP(B11,$O$15:$O$20,$N$15:$N$20)) -> 6 | C23: =IF(ISNUMBER(C11),C11,_xlfn.XLOOKUP(C$13,$L$2:$L$8,$N$2:$N$8)*_xlfn.XLOOKUP(C11,$O$15:$O$20,$N$15:$N$20)) -> #N/A | D23: =IF(ISNUMBER(D11),D11,_xlfn.XLOOKUP(D$13,$L$2:$L$8,$N$2:$N$8)*_xlfn.XLOOKUP(D11,$O$15:$O$20,$N$15:$N$20)) -> 10 | E23: =IF(ISNUMBER(E11),E11,_xlfn.XLOOKUP(E$13,$L$2:$L$8,$N$2:$N$8)*_xlfn.XLOOKUP(E11,$O$15:$O$20,$N$15:$N$20)) -> 9.6 | F23: =IF(ISNUMBER(F11),F11,_xlfn.XLOOKUP(F$13,$L$2:$L$8,$N$2:$N$8)*_xlfn.XLOOKUP(F11,$O$15:$O$20,$N$15:$N$20)) -> 7 | G23: =IF(ISNUMBER(G11),G11,_xlfn.XLOOKUP(G$13,$L$2:$L$8,$N$2:$N$8)*_xlfn.XLOOKUP(G11,$O$15:$O$20,$N$15:$N$20)) -> #N/A | H23: =IF(ISNUMBER(H11),H11,_xlfn.XLOOKUP(H$13,$L$2:$L$8,$N$2:$N$8)*_xlfn.XLOOKUP(H11,$O$15:$O$20,$N$15:$N$20)) -> #N/A
B25: C1 | C25: C2 | D25: C3 | E25: C4 | F25: C5A | G25: C5B | H25: C5C
A26: =A14 -> LINKS | B26: =B14/MAX($B$14:$B$23)*$N$2 -> 8 | C26: =C14/MAX($C$14:$C$23)*$N$3 -> #N/A | D26: =D14/MAX($D$14:$D$23)*$N$4 -> 5 | E26: =E14/MAX($E$14:$E$23)*$N$5 -> 25 | F26: =F14/MAX($F$14:$F$23)*$N$6 -> 24 | G26: =G14/MAX($G$14:$G$23)*$N$7 -> #N/A | H26: =H14/MAX($H$14:$H$23)*$N$8 -> #N/A
A27: =A15 -> ALTRO 1 | B27: =B15/MAX($B$14:$B$23)*$N$2 -> 8 | C27: =C15/MAX($C$14:$C$23)*$N$3 -> #N/A | D27: =D15/MAX($D$14:$D$23)*$N$4 -> 5 | E27: =E15/MAX($E$14:$E$23)*$N$5 -> 15 | F27: =F15/MAX($F$14:$F$23)*$N$6 -> 17.142857 | G27: =G15/MAX($G$14:$G$23)*$N$7 -> #N/A | H27: =H15/MAX($H$14:$H$23)*$N$8 -> #N/A
A28: =A16 -> ALTRO 2 | B28: =B16/MAX($B$14:$B$23)*$N$2 -> 6 | C28: =C16/MAX($C$14:$C$23)*$N$3 -> #N/A | D28: =D16/MAX($D$14:$D$23)*$N$4 -> 5 | E28: =E16/MAX($E$14:$E$23)*$N$5 -> 15 | F28: =F16/MAX($F$14:$F$23)*$N$6 -> 24 | G28: =G16/MAX($G$14:$G$23)*$N$7 -> #N/A | H28: =H16/MAX($H$14:$H$23)*$N$8 -> #N/A
A29: =A17 -> ALTRO 3 | B29: =B17/MAX($B$14:$B$23)*$N$2 -> 4 | C29: =C17/MAX($C$14:$C$23)*$N$3 -> #N/A | D29: =D17/MAX($D$14:$D$23)*$N$4 -> 5 | E29: =E17/MAX($E$14:$E$23)*$N$5 -> 25 | F29: =F17/MAX($F$14:$F$23)*$N$6 -> 17.142857 | G29: =G17/MAX($G$14:$G$23)*$N$7 -> #N/A | H29: =H17/MAX($H$14:$H$23)*$N$8 -> #N/A
A30: =A18 -> ALTRO 4 | B30: =B18/MAX($B$14:$B$23)*$N$2 -> 6 | C30: =C18/MAX($C$14:$C$23)*$N$3 -> #N/A | D30: =D18/MAX($D$14:$D$23)*$N$4 -> 5 | E30: =E18/MAX($E$14:$E$23)*$N$5 -> 25 | F30: =F18/MAX($F$14:$F$23)*$N$6 -> 17.142857 | G30: =G18/MAX($G$14:$G$23)*$N$7 -> #N/A | H30: =H18/MAX($H$14:$H$23)*$N$8 -> #N/A
A31: =A19 -> ALTRO 5 | B31: =B19/MAX($B$14:$B$23)*$N$2 -> 6 | C31: =C19/MAX($C$14:$C$23)*$N$3 -> #N/A | D31: =D19/MAX($D$14:$D$23)*$N$4 -> 5 | E31: =E19/MAX($E$14:$E$23)*$N$5 -> 25 | F31: =F19/MAX($F$14:$F$23)*$N$6 -> 17.142857 | G31: =G19/MAX($G$14:$G$23)*$N$7 -> #N/A | H31: =H19/MAX($H$14:$H$23)*$N$8 -> #N/A
A32: =A20 -> ALTRO 6 | B32: =B20/MAX($B$14:$B$23)*$N$2 -> 10 | C32: =C20/MAX($C$14:$C$23)*$N$3 -> #N/A | D32: =D20/MAX($D$14:$D$23)*$N$4 -> 5 | E32: =E20/MAX($E$14:$E$23)*$N$5 -> 10 | F32: =F20/MAX($F$14:$F$23)*$N$6 -> 17.142857 | G32: =G20/MAX($G$14:$G$23)*$N$7 -> #N/A | H32: =H20/MAX($H$14:$H$23)*$N$8 -> #N/A
A33: =A21 -> ALTRO 7 | B33: =B21/MAX($B$14:$B$23)*$N$2 -> 6 | C33: =C21/MAX($C$14:$C$23)*$N$3 -> #N/A | D33: =D21/MAX($D$14:$D$23)*$N$4 -> 5 | E33: =E21/MAX($E$14:$E$23)*$N$5 -> 25 | F33: =F21/MAX($F$14:$F$23)*$N$6 -> 17.142857 | G33: =G21/MAX($G$14:$G$23)*$N$7 -> #N/A | H33: =H21/MAX($H$14:$H$23)*$N$8 -> #N/A
A34: =A22 -> ALTRO 8 | B34: =B22/MAX($B$14:$B$23)*$N$2 -> 10 | C34: =C22/MAX($C$14:$C$23)*$N$3 -> #N/A | D34: =D22/MAX($D$14:$D$23)*$N$4 -> 5 | E34: =E22/MAX($E$14:$E$23)*$N$5 -> 25 | F34: =F22/MAX($F$14:$F$23)*$N$6 -> 17.142857 | G34: =G22/MAX($G$14:$G$23)*$N$7 -> #N/A | H34: =H22/MAX($H$14:$H$23)*$N$8 -> #N/A
A35: =A23 -> ALTRO 9 | B35: =B23/MAX($B$14:$B$23)*$N$2 -> 6 | C35: =C23/MAX($C$14:$C$23)*$N$3 -> #N/A | D35: =D23/MAX($D$14:$D$23)*$N$4 -> 2.5 | E35: =E23/MAX($E$14:$E$23)*$N$5 -> 10 | F35: =F23/MAX($F$14:$F$23)*$N$6 -> 24 | G35: =G23/MAX($G$14:$G$23)*$N$7 -> #N/A | H35: =H23/MAX($H$14:$H$23)*$N$8 -> #N/A

Sheet PUNTEGGIO ECONOMICO
B1: RIBASSO | C1: IMPORTO | D1: PUNTEGGIO | E1: DIFF
A2: ='PUNTEGGIO TECNICO'!A2 -> LINKS | B2: =(B13-C2)/B13 -> 0.90589758 | C2: =ECONOMICA!E10 -> 65420 | D2: =IFERROR($B$17*(MAX(0,B2)/MAX($B$2:$B$11))^$B$16,0) -> 20 | E2: =MAX(D2:D11)-D2 -> 0
A3: ='PUNTEGGIO TECNICO'!A3 -> ALTRO 1 | B3: =B14 -> 0.12 | C3: =$B$13*(1-B3) -> 611776 | D3: =IFERROR($B$17*(MAX(0,B3)/MAX($B$2:$B$11))^$B$16,0) -> 10.905878 | E3: =MAX(D3:D12)-D3 -> 4.346426
A4: ='PUNTEGGIO TECNICO'!A4 -> ALTRO 2 | B4: =B3*$B$15 -> 0.138 | C4: =$B$13*(1-B4) -> 599262.4 | D4: =IFERROR($B$17*(MAX(0,B4)/MAX($B$2:$B$11))^$B$16,0) -> 11.372868 | E4: =MAX(D4:D13)-D4 -> 3.8794363
A5: ='PUNTEGGIO TECNICO'!A5 -> ALTRO 3 | B5: =B4*$B$15 -> 0.1587 | C5: =$B$13*(1-B5) -> 584871.76 | D5: =IFERROR($B$17*(MAX(0,B5)/MAX($B$2:$B$11))^$B$16,0) -> 11.859854 | E5: =MAX(D5:D14)-D5 -> 3.3924501
A6: ='PUNTEGGIO TECNICO'!A6 -> ALTRO 4 | B6: =B5*$B$15 -> 0.182505 | C6: =$B$13*(1-B6) -> 568322.52 | D6: =IFERROR($B$17*(MAX(0,B6)/MAX($B$2:$B$11))^$B$16,0) -> 12.367693 | E6: =MAX(D6:D15)-D6 -> 2.8846111
A7: ='PUNTEGGIO TECNICO'!A7 -> ALTRO 5 | B7: =B6*$B$15 -> 0.20988075 | C7: =$B$13*(1-B7) -> 549290.9 | D7: =IFERROR($B$17*(MAX(0,B7)/MAX($B$2:$B$11))^$B$16,0) -> 12.897278 | E7: =MAX(D7:D16)-D7 -> 2.3550265
A8: ='PUNTEGGIO TECNICO'!A8 -> ALTRO 6 | B8: =B7*$B$15 -> 0.24136286 | C8: =$B$13*(1-B8) -> 527404.54 | D8: =IFERROR($B$17*(MAX(0,B8)/MAX($B$2:$B$11))^$B$16,0) -> 13.449539 | E8: =MAX(D8:D17)-D8 -> 1.8027651
A9: ='PUNTEGGIO TECNICO'!A9 -> ALTRO 7 | B9: =B8*$B$15 -> 0.27756729 | C9: =$B$13*(1-B9) -> 502235.22 | D9: =IFERROR($B$17*(MAX(0,B9)/MAX($B$2:$B$11))^$B$16,0) -> 14.025448 | E9: =MAX(D9:D18)-D9 -> 1.2268558
A10: ='PUNTEGGIO TECNICO'!A10 -> ALTRO 8 | B10: =B9*$B$15 -> 0.31920239 | C10: =$B$13*(1-B10) -> 473290.5 | D10: =IFERROR($B$17*(MAX(0,B10)/MAX($B$2:$B$11))^$B$16,0) -> 14.626018 | E10: =MAX(D10:D19)-D10 -> 0.6262861
A11: ='PUNTEGGIO TECNICO'!A11 -> ALTRO 9 | B11: =B10*$B$15 -> 0.36708274 | C11: =$B$13*(1-B11) -> 440004.08 | D11: =IFERROR($B$17*(MAX(0,B11)/MAX($B$2:$B$11))^$B$16,0) -> 15.252304 | E11: =MAX(D11:D20)-D11 -> 0
A13: BASE D'ASTA | B13: =GARA!B5 -> 695200
A14: RIBASSO PARTENZA | B14: 0.12
A15: MOLTIPLICATORE | B15: 1.15
A16: ESPONENTE/CORRETTIVO | B16: 0.3
A17: PUNTEGGIO MAX | B17: 20
A18: MIGLIORE OFFERTA | B18: =MIN(C2:C11) -> 65420
A19: MEDIA RIBASSI | B19: =AVERAGE(B2:B11) -> 0.29201986
A20: METODO PE | B20: rmax_nonlin — Non lineare sul ribasso massimo
A21: COEFFICIENTE X | B21: 0.85
A22: ESPRESSIONE PE | B22: 20 * (Ri/Rmax)^0.3

Sheet PUNTEGGIO TOTALE
B1: PT | C1: PE | D1: TOTALE | E1: DIFFERENZA
A2: ='PUNTEGGIO TECNICO'!A2 -> LINKS | B2: ='PUNTEGGIO TECNICO'!J2 -> #N/A | C2: ='PUNTEGGIO ECONOMICO'!D2 -> 20 | D2: =B2+C2 -> #N/A | E2: =D2-MAX($D$2:$D$11) -> #N/A
A3: ='PUNTEGGIO TECNICO'!A3 -> ALTRO 1 | B3: ='PUNTEGGIO TECNICO'!J3 -> #N/A | C3: ='PUNTEGGIO ECONOMICO'!D3 -> 10.905878 | D3: =B3+C3 -> #N/A | E3: =D3-MAX($D$2:$D$11) -> #N/A
A4: ='PUNTEGGIO TECNICO'!A4 -> ALTRO 2 | B4: ='PUNTEGGIO TECNICO'!J4 -> #N/A | C4: ='PUNTEGGIO ECONOMICO'!D4 -> 11.372868 | D4: =B4+C4 -> #N/A | E4: =D4-MAX($D$2:$D$11) -> #N/A
A5: ='PUNTEGGIO TECNICO'!A5 -> ALTRO 3 | B5: ='PUNTEGGIO TECNICO'!J5 -> #N/A | C5: ='PUNTEGGIO ECONOMICO'!D5 -> 11.859854 | D5: =B5+C5 -> #N/A | E5: =D5-MAX($D$2:$D$11) -> #N/A
A6: ='PUNTEGGIO TECNICO'!A6 -> ALTRO 4 | B6: ='PUNTEGGIO TECNICO'!J6 -> #N/A | C6: ='PUNTEGGIO ECONOMICO'!D6 -> 12.367693 | D6: =B6+C6 -> #N/A | E6: =D6-MAX($D$2:$D$11) -> #N/A
A7: ='PUNTEGGIO TECNICO'!A7 -> ALTRO 5 | B7: ='PUNTEGGIO TECNICO'!J7 -> #N/A | C7: ='PUNTEGGIO ECONOMICO'!D7 -> 12.897278 | D7: =B7+C7 -> #N/A | E7: =D7-MAX($D$2:$D$11) -> #N/A
A8: ='PUNTEGGIO TECNICO'!A8 -> ALTRO 6 | B8: ='PUNTEGGIO TECNICO'!J8 -> #N/A | C8: ='PUNTEGGIO ECONOMICO'!D8 -> 13.449539 | D8: =B8+C8 -> #N/A | E8: =D8-MAX($D$2:$D$11) -> #N/A
A9: ='PUNTEGGIO TECNICO'!A9 -> ALTRO 7 | B9: ='PUNTEGGIO TECNICO'!J9 -> #N/A | C9: ='PUNTEGGIO ECONOMICO'!D9 -> 14.025448 | D9: =B9+C9 -> #N/A | E9: =D9-MAX($D$2:$D$11) -> #N/A
A10: ='PUNTEGGIO TECNICO'!A10 -> ALTRO 8 | B10: ='PUNTEGGIO TECNICO'!J10 -> #N/A | C10: ='PUNTEGGIO ECONOMICO'!D10 -> 14.626018 | D10: =B10+C10 -> #N/A | E10: =D10-MAX($D$2:$D$11) -> #N/A
A11: ='PUNTEGGIO TECNICO'!A11 -> ALTRO 9 | B11: ='PUNTEGGIO TECNICO'!J11 -> #N/A | C11: ='PUNTEGGIO ECONOMICO'!D11 -> 15.252304 | D11: =B11+C11 -> #N/A | E11: =D11-MAX($D$2:$D$11) -> #N/A

Sheet COST MODEL
A1: COSTI INTERNI | H1: # | I1: VALORE (€) | J1: TOTALE (€)
A2: ATTIVITA' | B2: # | C2: COSTO (€) | D2: GG/U | E2: NOTE STIME | G2: COSTI INTERNI (€) | H2: =D54 -> 554.45 | I2: 220 | J2: =C54 -> 121979
A3: Offering | C3: =D3*$I$2 -> 0 | D3: 0 | G3: COSTI ESTERNI (€) | J3: =C63 -> 36393
A4: Management | B4: 0.1 | C4: =D4*$I$2 -> 10780 | D4: =ROUND(B4*SUM(D6,D5,D50,D51,D52),0) -> 49 | G4: MARGINE PRODUZIONE (%) | J4: 0.35 | K4: <-- INTRODURRE PERCENTUALE DI MARGINE %
A5: Phase In / Phase Out | C5: =D5*$I$2 -> 3300 | D5: 15 | E5: Attività di presa in carico dell'attuale | G5: MARGINE RIVENDITA (%) | J5: 0.25 | K5: <-- INTRODURRE PERCENTUALE DI MARGINE %
A6: Analisi e Sviluppo Software | C6: =D6*$I$2 -> 76780 | D6: =SUM(D7:D49) -> 349 | E6: L'OBIETTIVO E' RIDURRE LE GIORNATE A CIRCA 250 | G6: RICAVO DELLA PRODUZIONE (€) | J6: =(1/(1-J4))*J2 -> 187660
A7: FLUSSI - Proposte migliorative (es. flussi ottimizzati) | C7: =$I$2*D7 -> 1100 | D7: 5 | G7: RICAVO DA RIVENDITE (€) | J7: =(1/(1-J5))*J3 -> 48524
A8: FLUSSI - Analisi e progettazione | C8: =$I$2*D8 -> 2200 | D8: 10 | G8: RICAVO AUSPICABILE (€) | J8: =SUM(J6:J7) -> 236184
A9: FLUSSI - Sviluppo | C9: =$I$2*D9 -> 7260 | D9: 33 | G9: MARGINE DERIVABILE (€) | J9: =J8-(J2+J3) -> 77812
A10: DESIGN e TEMA - Analisi e design UX/UI 3 progetti grafici | C10: =$I$2*D10 -> 6600 | D10: 30 | G10: MARGINE COMMESSA (%) | J10: =J9/J8 -> 0.329455
A11: DESIGN e TEMA - Sviluppo tema grafico | C11: =$I$2*D11 -> 2200 | D11: 10 | G11: % LINKS IN RTI | J11: 1
A12: MICROSERVIZI - Gestione erogazioni | C12: =$I$2*D12 -> 1760 | D12: 8 | G12: RICAVO LINKS DA ACCORDI | J12: =ECONOMICA!E10 -> 65420
A13: MICROSERVIZI - Gestione Enti beneficiari (e anagrafiche spettacolo) | C13: =$I$2*D13 -> 1760 | D13: 8 | G13: MARGINE (€) | J13: =J12-(J2+J3) -> -92952
A14: MICROSERVIZI - Statistiche e reportistica | C14: =$I$2*D14 -> 1760 | D14: 8 | G14: MARGINE COMMESSA (%) | J14: =J13/J12 -> -1.4208499
A15: MICROSERVIZI - Notifiche | C15: =$I$2*D15 -> 1760 | D15: 8
A16: MICROSERVIZI - Interventi (in ed extra Art Bonus) | C16: =$I$2*D16 -> 1760 | D16: 8
A17: MICROSERVIZI - Transazioni | C17: =$I$2*D17 -> 1760 | D17: 8
A18: MICROSERVIZI - Autenticazione | C18: =$I$2*D18 -> 1760 | D18: 8
A19: MICROSERVIZI - Gestione Concorso Art Bonus | C19: =$I$2*D19 -> 1320 | D19: 6
A20: MICROSERVIZI - Harvesting ETL (Business continuity) | C20: =$I$2*D20 -> 1100 | D20: 5
A21: MICROSERVIZI - Integrazione con Cookiebot | C21: =$I$2*D21 -> 440 | D21: 2
A22: MICROSERVIZI - Integrazione con Zendesk (Ticketing) | C22: =$I$2*D22 -> 440 | D22: 2
A23: MICROSERVIZI - Integrazione con Mailup | C23: =$I$2*D23 -> 440 | D23: 2
A24: PORTLET FE - Gestione erogazioni | C24: =$I$2*D24 -> 2200 | D24: 10
A25: PORTLET FE - Gestione Enti beneficiari (e anagrafiche spettacolo) | C25: =$I$2*D25 -> 2200 | D25: 10
A26: PORTLET FE - Statistiche e reportistica | C26: =$I$2*D26 -> 2200 | D26: 10
... A49: PRODUZIONE DOCUMENTI TECNICI | C49: =$I$2*D49 -> 3300 | D49: 15
A50: Formazione | C50: =D50*$I$2 -> 1760 | D50: 8
A51: MAC + MAD | C51: =D51*$I$2 -> 15840 | D51: =3*24 -> 72 | E51: 3 gg/uu per 24 + 5 mesi
A52: MEV | C52: =D52*$I$2 -> 9680 | D52: =66/1.5 -> 44 | E52: fatt. prod. 1,5 : 66 --> 44
A53: Contingency | B53: 0.05 | C53: =D53*$I$2 -> 3839 | D53: =D6*B53 -> 17.45
C54: =SUM(C3:C6,C50:C53) -> 121979 | D54: =SUM(D3:D6,D50:D53) -> 554.45
A56: COSTI ESTERNI
A57: ATTIVITA' / DELIVERABLE / FORNITURA | B57: FORNITORE | C57: COSTO (€) | D57: PREVENTIVO / NOTE
A58: Mailup (licenza) | B58: MAILUP | C58: 7020 | E58: Per 27 mesi
A59: ZenDesk (licenza) | B59: ZENDESK | C59: 1863 | E59: Per 27 mesi
A60: Hosting | B60: VIANOVA | C60: 26160 | E60: Stima ricevuta da Danilo, no offerta, OBIETTIVO RIDURRE IL COSTO A CIRCA 20K
A61: Cookiebot | C61: 1350 | E61: Per 27 mesi
C63: =SUM(C58:C62) -> 36393

Sheet GIUSTIFICAZIONE
A1: VOCE DI COSTO | B1: % INCIDENZA | C1: COSTO TOTALE | D1: %
A2: Voce n. 1 - Totale Costo della manodopera diretta | C2: ='MANODOPERA DA CCNL'!M12 -> 127661.68 | D2: =C2/$C$10 -> 0.74993647
A3: Voce n. 1 - Totale Costo della manodopera da subappalto | C3: ='MANODOPERA DA CCNL'!E42 -> 0 | D3: =C3/$C$10 -> 0
A4: Voce n. 2.1 - Spese Generali - Costi generali di struttura | B4: 0.03 | C4: =B4*C2 -> 3829.8503 | D4: =C4/$C$10 -> 0.022498094 | E4: <-- INCIDE TOT % SUL COSTO DELLA MANODOPERA
A5: Voce n. 2.2 - Spese Generali - Costi amministrativi e finanziari | B5: 0.02 | C5: =B5*C11 -> 1308.4 | D5: =C5/$C$10 -> 0.0076860723 | E5: <-- INCIDE TOT % SUL FATTURATO DELLA COMMESSA
A6: Voce n. 3 - Costi relativi all’ammortamento o leasing dei mezzi | B6: 1.06 | C6: =B6*'MANODOPERA DA CCNL'!L12 -> 644.48 | D6: =C6/$C$10 -> 0.0037859369 | E6: <-- INCIDE TOT € PER NR. DI GG/UU EROGATE
A7: Voce n. 4 - Materiali specifici per l’esecuzione dei servizi | D7: =C7/$C$10 -> 0 | E7: <-- FORNITURE DI ATTREZZATURE, HW, SW, ECC. DICHIARATI
A8: Voce n. 5 - Oneri per la sicurezza aziendali | B8: ='ONERI SICUREZZA'!C25*2 -> 0.64569287 | C8: =B8*'MANODOPERA DA CCNL'!L12 -> 392.58126 | D8: =C8/$C$10 -> 0.0023061816 | E8: <-- DA MOLTIPLICARE X IL NUMERO DI GG/UU EROGATE
A9: Voce n. 6 - Altro (specificare) | C9: ='COST MODEL'!C63 -> 36393 | D9: =C9/$C$10 -> 0.21378724 | E9: <-- ALTRI COSTI EVENTUALMENTE DA SOSTENERE
A10: COSTO TOTALE IVA ESCLUSA | C10: =SUM(C2:C9) -> 170229.99
A11: RICAVO TOTALE IVA ESCLUSA | C11: =ECONOMICA!E10 -> 65420
A12: Voce n. 7 – Utile d’impresa | B12: =C12/C11 -> -1.6021093 | C12: =C11-C10 -> -104809.99

Sheet MANODOPERA DA CCNL
A1: COSTI CCNL TEAM MIX
A2: Nr. | B2: RUOLO | C2: LIV. 1 | D2: LIV. 2 | E2: % LIV. 1 | F2: % LIV. 2 | G2: CCNL 1 | H2: CCNL 2 | I2: MEDIO LINKS | J2: Nr. | K2: ELAPSED | L2: GG/UU | M2: TOTALE COSTI
A3: 1 | B3: CAPO PROGETTO | C3: 8Q | E3: 1 | F3: =1-E3 -> 0 | G3: =IF(C3<>"",_xlfn.XLOOKUP('MANODOPERA DA CCNL'!C3,CCNL!$C$3:$L$3,CCNL!$C$27:$L$27),0) -> 253.90088 | H3: =IF(D3<>"",_xlfn.XLOOKUP('MANODOPERA DA CCNL'!D3,CCNL!$C$3:$L$3,CCNL!$C$27:$L$27),0) -> 0 | I3: =IF(D3="",G3,(G3*E3+H3*F3)) -> 253.90088 | L3: =ROUND($C$16*N3,0) -> 43 | M3: =L3*I3 -> 10917.738 | N3: 0.07
A4: 2 | B4: TECHNICAL ARCHITECT | C4: 7 | E4: 1 | F4: =1-E4 -> 0 | G4: =IF(C4<>"",_xlfn.XLOOKUP('MANODOPERA DA CCNL'!C4,CCNL!$C$3:$L$3,CCNL!$C$27:$L$27),0) -> 225.00445 | H4: =IF(D4<>"",_xlfn.XLOOKUP('MANODOPERA DA CCNL'!D4,CCNL!$C$3:$L$3,CCNL!$C$27:$L$27),0) -> 0 | I4: =IF(D4="",G4,(G4*E4+H4*F4)) -> 225.00445 | L4: =ROUND($C$16*N4,0) -> 61 | M4: =L4*I4 -> 13725.271 | N4: 0.1
A5: 3 | B5: DEVELOPER | C5: 5 | D5: 6 | E5: 0.5 | F5: =1-E5 -> 0.5 | G5: =IF(C5<>"",_xlfn.XLOOKUP('MANODOPERA DA CCNL'!C5,CCNL!$C$3:$L$3,CCNL!$C$27:$L$27),0) -> 195.70108 | H5: =IF(D5<>"",_xlfn.XLOOKUP('MANODOPERA DA CCNL'!D5,CCNL!$C$3:$L$3,CCNL!$C$27:$L$27),0) -> 209.6573 | I5: =IF(D5="",G5,(G5*E5+H5*F5)) -> 202.67919 | L5: =ROUND($C$16*N5,0) -> 262 | M5: =L5*I5 -> 53101.949 | N5: 0.43
A6: 4 | B6: UX UI EXPERT | C6: 7 | E6: 1 | F6: =1-E6 -> 0 | G6: =IF(C6<>"",_xlfn.XLOOKUP('MANODOPERA DA CCNL'!C6,CCNL!$C$3:$L$3,CCNL!$C$27:$L$27),0) -> 225.00445 | H6: =IF(D6<>"",_xlfn.XLOOKUP('MANODOPERA DA CCNL'!D6,CCNL!$C$3:$L$3,CCNL!$C$27:$L$27),0) -> 0 | I6: =IF(D6="",G6,(G6*E6+H6*F6)) -> 225.00445 | L6: =ROUND($C$16*N6,0) -> 49 | M6: =L6*I6 -> 11025.218 | N6: 0.08
A7: 6 | B7: SEO EXPERT | C7: 6 | E7: 1 | F7: =1-E7 -> 0 | G7: =IF(C7<>"",_xlfn.XLOOKUP('MANODOPERA DA CCNL'!C7,CCNL!$C$3:$L$3,CCNL!$C$27:$L$27),0) -> 209.6573 | H7: =IF(D7<>"",_xlfn.XLOOKUP('MANODOPERA DA CCNL'!D7,CCNL!$C$3:$L$3,CCNL!$C$27:$L$27),0) -> 0 | I7: =IF(D7="",G7,(G7*E7+H7*F7)) -> 209.6573 | L7: =ROUND($C$16*N7,0) -> 30 | M7: =L7*I7 -> 6289.7191 | N7: 0.05
A8: 7 | B8: DBA | C8: 7 | E8: 1 | F8: =1-E8 -> 0 | G8: =IF(C8<>"",_xlfn.XLOOKUP('MANODOPERA DA CCNL'!C8,CCNL!$C$3:$L$3,CCNL!$C$27:$L$27),0) -> 225.00445 | H8: =IF(D8<>"",_xlfn.XLOOKUP('MANODOPERA DA CCNL'!D8,CCNL!$C$3:$L$3,CCNL!$C$27:$L$27),0) -> 0 | I8: =IF(D8="",G8,(G8*E8+H8*F8)) -> 225.00445 | L8: =ROUND($C$16*N8,0) -> 30 | M8: =L8*I8 -> 6750.1334 | N8: 0.05
A9: 8 | B9: SISTEMISTA | C9: 6 | D9: 7 | E9: 0.5 | F9: =1-E9 -> 0.5 | G9: =IF(C9<>"",_xlfn.XLOOKUP('MANODOPERA DA CCNL'!C9,CCNL!$C$3:$L$3,CCNL!$C$27:$L$27),0) -> 209.6573 | H9: =IF(D9<>"",_xlfn.XLOOKUP('MANODOPERA DA CCNL'!D9,CCNL!$C$3:$L$3,CCNL!$C$27:$L$27),0) -> 225.00445 | I9: =IF(D9="",G9,(G9*E9+H9*F9)) -> 217.33087 | L9: =ROUND($C$16*N9,0) -> 30 | M9: =L9*I9 -> 6519.9262 | N9: 0.05
A10: 9 | B10: OPERATORE DI HD | C10: 4 | E10: 1 | F10: =1-E10 -> 0 | G10: =IF(C10<>"",_xlfn.XLOOKUP('MANODOPERA DA CCNL'!C10,CCNL!$C$3:$L$3,CCNL!$C$27:$L$27),0) -> 182.76561 | H10: =IF(D10<>"",_xlfn.XLOOKUP('MANODOPERA DA CCNL'!D10,CCNL!$C$3:$L$3,CCNL!$C$27:$L$27),0) -> 0 | I10: =IF(D10="",G10,(G10*E10+H10*F10)) -> 182.76561 | L10: =ROUND($C$16*N10,0) -> 91 | M10: =L10*I10 -> 16631.671 | N10: 0.15
A11: 10 | B11: FORMATORE | C11: 7 | E11: 1 | F11: =1-E11 -> 0 | G11: =IF(C11<>"",_xlfn.XLOOKUP('MANODOPERA DA CCNL'!C11,CCNL!$C$3:$L$3,CCNL!$C$27:$L$27),0) -> 225.00445 | H11: =IF(D11<>"",_xlfn.XLOOKUP('MANODOPERA DA CCNL'!D11,CCNL!$C$3:$L$3,CCNL!$C$27:$L$27),0) -> 0 | I11: =IF(D11="",G11,(G11*E11+H11*F11)) -> 225.00445 | L11: =ROUND($C$16*N11,0) -> 12 | M11: =L11*I11 -> 2700.0533 | N11: 0.02
J12: =SUM(J3:J11) -> 0 | L12: =SUM(L3:L11) -> 608 | M12: =SUM(M3:M11) -> 127661.68 | N12: =SUM(N3:N11) -> 1
B14: DA COST MODEL | C14: ='COST MODEL'!D54 -> 554.45
B15: INCREMENTO | C15: 1.1
B16: TOTALE GG/UU | C16: =C14*C15 -> 609.895

Sheet CCNL
A1: Costo del personale per livelli CCNL Metalmeccanica PMI - Confapi
B3: NR | C3: 9Q | D3: 9 | E3: 8Q | F3: 8 | G3: 7 | H3: 6 | I3: 5 | J3: 4 | K3: 3
A4: Retribuzione tabellare | C4: =2985.18 -> 2985.18 | D4: =2985.18 -> 2985.18 | E4: 2684.27 | F4: 2684.27 | G4: 2468.33 | H4: 2300.75 | I4: 2145.87 | J4: 2003.23 | K4: 1920
A5: Elemento retributivo | C5: 59.39 | D5: 59.39 | E5: 59.39 | F5: 59.39
A6: Indennità di funzione | C6: 69.72 | E6: 49.06
A7: Scatti di anzianità (pref. 3) | B7: 3 | C7: =45.96*B7 -> 137.88 | D7: =45.96*B7 -> 137.88 | E7: =40.95*B7 -> 122.85 | F7: =40.95*B7 -> 122.85 | G7: =36.41*B7 -> 109.23 | H7: =32.43*B7 -> 97.29 | I7: =29.64*B7 -> 88.92 | J7: =26.75*B7 -> 80.25 | K7: =25.05*B7 -> 75.15
A8: Elemento perequativo (obbligatorio? 40,42€) | B8: 40.416667 | C8: =$B$8 -> 40.416667 | D8: =$B$8 -> 40.416667 | E8: =$B$8 -> 40.416667 | F8: =$B$8 -> 40.416667 | G8: =$B$8 -> 40.416667 | H8: =$B$8 -> 40.416667 | I8: =$B$8 -> 40.416667 | J8: =$B$8 -> 40.416667 | K8: =$B$8 -> 40.416667
A9: Mancata adesione alla bilateralità (opzionale? 5,00 €) | B9: 5 | C9: =$B$9 -> 5 | D9: =$B$9 -> 5 | E9: =$B$9 -> 5 | F9: =$B$9 -> 5 | G9: =$B$9 -> 5 | H9: =$B$9 -> 5 | I9: =$B$9 -> 5 | J9: =$B$9 -> 5 | K9: =$B$9 -> 5
A10: Retribuzione diretta | C10: =SUM(C4:C9) -> 3297.5867 | D10: =SUM(D4:D9) -> 3227.8667 | E10: =SUM(E4:E9) -> 2960.9867 | F10: =SUM(F4:F9) -> 2911.9267 | G10: =SUM(G4:G9) -> 2622.9767 | H10: =SUM(H4:H9) -> 2443.4567 | I10: =SUM(I4:I9) -> 2280.2067 | J10: =SUM(J4:J9) -> 2128.8967 | K10: =SUM(K4:K9) -> 2040.5667
A11: Ex festività (4 novembre) | C11: =(C4+C5+C6+C7)/26*1/12 -> 10.423622 | D11: =(D4+D5+D6+D7)/26*1/12 -> 10.20016 | E11: =(E4+E5+E6+E7)/26*1/12 -> 9.3447756 | F11: =(F4+F5+F6+F7)/26*1/12 -> 9.1875321 | G11: =(G4+G5+G6+G7)/26*1/12 -> 8.2614103 | H11: =(H4+H5+H6+H7)/26*1/12 -> 7.6860256 | I11: =(I4+I5+I6+I7)/26*1/12 -> 7.1627885 | J11: =(J4+J5+J6+J7)/26*1/12 -> 6.6778205 | K11: =(K4+K5+K6+K7)/26*1/12 -> 6.3947115
A12: Retribuzione indiretta | C12: =C11 -> 10.423622 | D12: =D11 -> 10.20016 | E12: =E11 -> 9.3447756 | F12: =F11 -> 9.1875321 | G12: =G11 -> 8.2614103 | H12: =H11 -> 7.6860256 | I12: =I11 -> 7.1627885 | J12: =J11 -> 6.6778205 | K12: =K11 -> 6.3947115
A13: Retribuzione differita: Tredicesima mensilità | C13: =(C4+C5+C6+C7)/12 -> 271.01417 | D13: =(D4+D5+D6+D7)/12 -> 265.20417 | E13: =(E4+E5+E6+E7)/12 -> 242.96417 | F13: =(F4+F5+F6+F7)/12 -> 238.87583 | G13: =(G4+G5+G6+G7)/12 -> 214.79667 | H13: =(H4+H5+H6+H7)/12 -> 199.83667 | I13: =(I4+I5+I6+I7)/12 -> 186.2325 | J13: =(J4+J5+J6+J7)/12 -> 173.62333 | K13: =(K4+K5+K6+K7)/12 -> 166.2625
A14: Totale Retribuzione | C14: =C10+C12+C13+C11 -> 3589.4481 | D14: =D10+D12+D13+D11 -> 3513.4712 | E14: =E10+E12+E13+E11 -> 3222.6404 | F14: =F10+F12+F13+F11 -> 3169.1776 | G14: =G10+G12+G13+G11 -> 2854.2962 | H14: =H10+H12+H13+H11 -> 2658.6654 | I14: =I10+I12+I13+I11 -> 2480.7647 | J14: =J10+J12+J13+J11 -> 2315.8756 | K14: =K10+K12+K13+K11 -> 2219.6186
A15: Contributi Inps (29,36%) | B15: 0.2936 | C15: =C14*$B$15 -> 1053.862 | D15: =D14*$B$15 -> 1031.5551 | E15: =E14*$B$15 -> 946.16722 | F15: =F14*$B$15 -> 930.47053 | G15: =G14*$B$15 -> 838.02135 | H15: =H14*$B$15 -> 780.58416 | I15: =I14*$B$15 -> 728.35253 | J15: =J14*$B$15 -> 679.94109 | K15: =K14*$B$15 -> 651.68002
A16: Contributi Inail (0,475 per mille) | B16: =4.75/1000 -> 0.00475 | C16: =(C10)*$B$16 -> 15.663537 | D16: =(D10)*$B$16 -> 15.332367 | E16: =(E10)*$B$16 -> 14.064687 | F16: =(F10)*$B$16 -> 13.831652 | G16: =(G10)*$B$16 -> 12.459139 | H16: =(H10)*$B$16 -> 11.606419 | I16: =(I10)*$B$16 -> 10.830982 | J16: =(J10)*$B$16 -> 10.112259 | K16: =(K10)*$B$16 -> 9.6926917
A17: Contributi Obbligatori | C17: =C15+C16 -> 1069.5255 | D17: =D15+D16 -> 1046.8875 | E17: =E15+E16 -> 960.2319 | F17: =F15+F16 -> 944.30218 | G17: =G15+G16 -> 850.48049 | H17: =H15+H16 -> 792.19058 | I17: =I15+I16 -> 739.18351 | J17: =J15+J16 -> 690.05335 | K17: =K15+K16 -> 661.37271
A18: Trattamento fine rapporto | B18: 13.5 | C18: =(C14-C9-C8)/$B$18 -> 262.52085 | D18: =(D14-D9-D8)/$B$18 -> 256.89292 | E18: =(E14-E9-E8)/$B$18 -> 235.34991 | F18: =(F14-F9-F8)/$B$18 -> 231.3897 | G18: =(G14-G9-G8)/$B$18 -> 208.06515 | H18: =(H14-H9-H8)/$B$18 -> 193.57398 | I18: =(I14-I9-I8)/$B$18 -> 180.39615 | J18: =(J14-J9-J8)/$B$18 -> 168.18215 | K18: =(K14-K9-K8)/$B$18 -> 161.05199
A19: Rivalutazione TFR (1,81886%) | B19: 0.0181886 | C19: =C18*$B$19 -> 4.7748866 | D19: =D18*$B$19 -> 4.6725227 | E19: =E18*$B$19 -> 4.2806853 | F19: =F18*$B$19 -> 4.2086546 | G19: =G18*$B$19 -> 3.7844137 | H19: =H18*$B$19 -> 3.5208397 | I19: =I18*$B$19 -> 3.2811535 | J19: =J18*$B$19 -> 3.0589978 | K19: =K18*$B$19 -> 2.9293103
A20: Fondo Fondapi (contr. Az. 2%) | B20: 0.02 | C20: =(C14-C9-C8)*$B$20 -> 70.880628 | D20: =(D14-D9-D8)*$B$20 -> 69.36109 | E20: =(E14-E9-E8)*$B$20 -> 63.544474 | F20: =(F14-F9-F8)*$B$20 -> 62.475218 | G20: =(G14-G9-G8)*$B$20 -> 56.17759 | H20: =(H14-H9-H8)*$B$20 -> 52.264974 | I20: =(I14-I9-I8)*$B$20 -> 48.706962 | J20: =(J14-J9-J8)*$B$20 -> 45.409179 | K20: =(K14-K9-K8)*$B$20 -> 43.484038
A21: Assistenza sanitaria integrativa (8 €) | B21: 8 | C21: =$B$21 -> 8 | D21: =$B$21 -> 8 | E21: =$B$21 -> 8 | F21: =$B$21 -> 8 | G21: =$B$21 -> 8 | H21: =$B$21 -> 8 | I21: =$B$21 -> 8 | J21: =$B$21 -> 8 | K21: =$B$21 -> 8
A22: Contributi previdenza integrativa (1,8%) | B22: 0.018 | C22: =(C4+C5+C6+C7+C13)*1.8/100 -> 63.417315 | D22: =(D4+D5+D6+D7+D13)*1.8/100 -> 62.057775 | E22: =(E4+E5+E6+E7+E13)*1.8/100 -> 56.853615 | F22: =(F4+F5+F6+F7+F13)*1.8/100 -> 55.896945 | G22: =(G4+G5+G6+G7+G13)*1.8/100 -> 50.26242 | H22: =(H4+H5+H6+H7+H13)*1.8/100 -> 46.76178 | I22: =(I4+I5+I6+I7+I13)*1.8/100 -> 43.578405 | J22: =(J4+J5+J6+J7+J13)*1.8/100 -> 40.62786 | K22: =(K4+K5+K6+K7+K13)*1.8/100 -> 38.905425
A23: Welfare (16,67 €) | B23: 16.67 | C23: =$B$23 -> 16.67 | D23: =$B$23 -> 16.67 | E23: =$B$23 -> 16.67 | F23: =$B$23 -> 16.67 | G23: =$B$23 -> 16.67 | H23: =$B$23 -> 16.67 | I23: =$B$23 -> 16.67 | J23: =$B$23 -> 16.67 | K23: =$B$23 -> 16.67
A24: COSTO MENSILE | C24: =C14+C17+C18+C22+C21+C23+C19+C20 -> 5085.2372 | D24: =D14+D17+D18+D22+D21+D23+D19+D20 -> 4978.013 | E24: =E14+E17+E18+E22+E21+E23+E19+E20 -> 4567.571 | F24: =F14+F17+F18+F22+F21+F23+F19+F20 -> 4492.1203 | G24: =G14+G17+G18+G22+G21+G23+G19+G20 -> 4047.7362 | H24: =H14+H17+H18+H22+H21+H23+H19+H20 -> 3771.6475 | I24: =I14+I17+I18+I22+I21+I23+I19+I20 -> 3520.5809 | J24: =J14+J17+J18+J22+J21+J23+J19+J20 -> 3287.8772 | K24: =K14+K17+K18+K22+K21+K23+K19+K20 -> 3152.0321
A25: COSTO ANNUO | C25: =C24*12 -> 61022.847 | D25: =D24*12 -> 59736.156 | E25: =E24*12 -> 54810.852 | F25: =F24*12 -> 53905.443 | G25: =G24*12 -> 48572.835 | H25: =H24*12 -> 45259.77 | I25: =I24*12 -> 42246.971 | J25: =J24*12 -> 39454.526 | K25: =K24*12 -> 37824.385
A26: COSTO ORARIO | C26: =C25/$B40 -> 35.334596 | D26: =D25/$B40 -> 34.589552 | E26: =E25/$B40 -> 31.73761 | F26: =F25/$B40 -> 31.213343 | G26: =G25/$B40 -> 28.125556 | H26: =H25/$B40 -> 26.207163 | I26: =I25/$B40 -> 24.462635 | J26: =J25/$B40 -> 22.845701 | K26: =K25/$B40 -> 21.901786
A27: COSTO GIORNALIERO | C27: =C26*8 -> 282.67677 | D27: =D26*8 -> 276.71641 | E27: =E26*8 -> 253.90088 | F27: =F26*8 -> 249.70674 | G27: =G26*8 -> 225.00445 | H27: =H26*8 -> 209.6573 | I27: =I26*8 -> 195.70108 | J27: =J26*8 -> 182.76561 | K27: =K26*8 -> 175.21429
A30: Calcolo giornate lavorative | B30: Ore
A31: Ore annue lavorabili 2024 (52,2 sett.*40 ore) | B31: =2088+8 -> 2096 | C31: comprensivo del 29 febbraio
A32: Ore annue mediamente non lavorate così suddivise:
A33: ferie (20 giorni) | B33: 160
A34: permessi annui retribuiti (ROL + Ex festività) | B34: 104
A35: festività ( 8 giorni esclusi sabati e dom.) | B35: 64
A36: assemblee, permessi sindacali, diritto allo studio | B36: 0
A37: malattia, infort., maternità | B37: 25
A38: formazione obbligatoria e non | B38: 16
A39: Totale ore non lavorate | B39: =SUM(B33:B38) -> 369
A40: Ore annue mediamente lavorate | B40: =B31-B39 -> 1727
A41: Giorni annui mediamente lavorati | B41: =B40/8 -> 215.875

Sheet CCNL APPRENDISTI
A1: Costo del personale per livelli CCNL Metalmeccanica PMI - Confapi
B3: NR | C3: 6 | D3: 5 | E3: 4 | F3: 3
A4: Retribuzione tabellare | C4: 2300.75 | D4: 2145.87 | E4: 2003.23 | F4: 1920
A5: Elemento retributivo
A6: Indennità di funzione
A7: Scatti di anzianità (pref. 3) | B7: 1 | C7: =32.43*B7 -> 32.43
A8: Elemento perequativo (obbligatorio? 40,42€) | B8: 40.416667 | C8: =$B$8 -> 40.416667 | D8: =$B$8 -> 40.416667 | E8: =$B$8 -> 40.416667 | F8: =$B$8 -> 40.416667
A9: Mancata adesione alla bilateralità (opzionale? 5,00 €) | B9: 5 | C9: =$B$9 -> 5 | D9: =$B$9 -> 5 | E9: =$B$9 -> 5 | F9: =$B$9 -> 5
A10: Retribuzione diretta | C10: =SUM(C4:C9) -> 2378.5967 | D10: =SUM(D4:D9) -> 2191.2867 | E10: =SUM(E4:E9) -> 2048.6467 | F10: =SUM(F4:F9) -> 1965.4167
A11: Ex festività (4 novembre) | C11: =(C4+C5+C6+C7)/26*1/12 -> 7.478141 | D11: =(D4+D5+D6+D7)/26*1/12 -> 6.8777885 | E11: =(E4+E5+E6+E7)/26*1/12 -> 6.420609 | F11: =(F4+F5+F6+F7)/26*1/12 -> 6.1538462
A12: Retribuzione indiretta | C12: =C11 -> 7.478141 | D12: =D11 -> 6.8777885 | E12: =E11 -> 6.420609 | F12: =F11 -> 6.1538462
A13: Retribuzione differita: Tredicesima mensilità | C13: =(C4+C5+C6+C7)/12 -> 194.43167 | D13: =(D4+D5+D6+D7)/12 -> 178.8225 | E13: =(E4+E5+E6+E7)/12 -> 166.93583 | F13: =(F4+F5+F6+F7)/12 -> 160
A14: Totale Retribuzione | C14: =C10+C12+C13+C11 -> 2587.9846 | D14: =D10+D12+D13+D11 -> 2383.8647 | E14: =E10+E12+E13+E11 -> 2228.4237 | F14: =F10+F12+F13+F11 -> 2137.7244
A15: Contributi Inps (29,36%) | B15: 0.1 | C15: =C14*$B$15 -> 258.79846 | D15: =D14*$B$15 -> 238.38647 | E15: =E14*$B$15 -> 222.84237 | F15: =F14*$B$15 -> 213.77244
A16: Contributi Inail (0,475 per mille) | B16: =4.75/1000 -> 0.00475 | C16: =(C10)*$B$16 -> 11.298334 | D16: =(D10)*$B$16 -> 10.408612 | E16: =(E10)*$B$16 -> 9.7310717 | F16: =(F10)*$B$16 -> 9.3357292
A17: Contributi Obbligatori | C17: =C15+C16 -> 270.0968 | D17: =D15+D16 -> 248.79509 | E17: =E15+E16 -> 232.57344 | F17: =F15+F16 -> 223.10817
A18: Trattamento fine rapporto | B18: 13.5 | C18: =(C14-C9-C8)/$B$18 -> 188.33837 | D18: =(D14-D9-D8)/$B$18 -> 173.21838 | E18: =(E14-E9-E8)/$B$18 -> 161.70423 | F18: =(F14-F9-F8)/$B$18 -> 154.98575
A19: Rivalutazione TFR (1,81886%) | B19: 0.0181886 | C19: =C18*$B$19 -> 3.4256112 | D19: =D18*$B$19 -> 3.1505998 | E19: =E18*$B$19 -> 2.9411735 | F19: =F18*$B$19 -> 2.8189739
A20: Fondo Fondapi (contr. Az. 2%) | B20: 0 | C20: =(C14-C9-C8)*$B$20 -> 0 | D20: =(D14-D9-D8)*$B$20 -> 0 | E20: =(E14-E9-E8)*$B$20 -> 0 | F20: =(F14-F9-F8)*$B$20 -> 0
A21: Assistenza sanitaria integrativa (8 €) | B21: 8 | C21: =$B$21 -> 8 | D21: =$B$21 -> 8 | E21: =$B$21 -> 8 | F21: =$B$21 -> 8
A22: Contributi previdenza integrativa (1,8%) | B22: 0.018 | C22: =(C4+C5+C6+C7+C13)*1.8/100 -> 45.49701 | D22: =(D4+D5+D6+D7+D13)*1.8/100 -> 41.844465 | E22: =(E4+E5+E6+E7+E13)*1.8/100 -> 39.062985 | F22: =(F4+F5+F6+F7+F13)*1.8/100 -> 37.44
A23: Welfare (16,67 €) | B23: 16.67 | C23: =$B$23 -> 16.67 | D23: =$B$23 -> 16.67 | E23: =$B$23 -> 16.67 | F23: =$B$23 -> 16.67
A24: COSTO MENSILE | C24: =C14+C17+C18+C22+C21+C23+C19+C20 -> 3120.0124 | D24: =D14+D17+D18+D22+D21+D23+D19+D20 -> 2875.5433 | E24: =E14+E17+E18+E22+E21+E23+E19+E20 -> 2689.3755 | F24: =F14+F17+F18+F22+F21+F23+F19+F20 -> 2580.7473
A25: COSTO ANNUO | C25: =C24*12 -> 37440.149 | D25: =D24*12 -> 34506.519 | E25: =E24*12 -> 32272.507 | F25: =F24*12 -> 30968.967
A26: COSTO ORARIO | C26: =C25/$B40 -> 21.679299 | D26: =D25/$B40 -> 19.980613 | E26: =E25/$B40 -> 18.687033 | F26: =F25/$B40 -> 17.932233
A27: COSTO GIORNALIERO | C27: =C26*8 -> 173.43439 | D27: =D26*8 -> 159.84491 | E27: =E26*8 -> 149.49627 | F27: =F26*8 -> 143.45787
A30: Calcolo giornate lavorative | B30: Ore
A31: Ore annue lavorabili 2024 (52,2 sett.*40 ore) | B31: =2088+8 -> 2096
A32: Ore annue mediamente non lavorate così suddivise:
A33: ferie (20 giorni) | B33: 160
A34: permessi annui retribuiti (ROL + Ex festività) | B34: 104
A35: festività ( 8 giorni esclusi sabati e dom.) | B35: 64
A36: assemblee, permessi sindacali, diritto allo studio | B36: 0
A37: malattia, infort., maternità | B37: 25
A38: formazione obbligatoria e non | B38: 16
A39: Totale ore non lavorate | B39: =SUM(B33:B38) -> 369
A40: Ore annue mediamente lavorate | B40: =B31-B39 -> 1727
A41: Giorni annui mediamente lavorati | B41: =B40/8 -> 215.875

Sheet ONERI SICUREZZA
A1: VOCE DI COSTO ONERI DI SICUREZZA AZIENDALI
A3: Per le attività svolte dal Servizio di Prevenzione e Protezione dai Rischi | C3: =SUM(C4:C5) -> 5610.0822 | D3: =C3/C24 -> 0.14681427
B4: Responsabile Servizio Prevenzione e Protezione | C4: =CCNL!I27*20 -> 3914.0216 | E4: 20 giorni all'anno dedicati dal RSPP per tematiche di sicurezza sul lavoro al costo di un 5° livello per gg/uu
B5: Riunione Periodica | C5: =(4*6*CCNL!C26)*2 -> 1696.0606 | E5: Costo di due riunioni periodiche annunali di 4 ore con 6 responsabili (costo medio orario più elevato 9q)
A6: Per la Formazione, Informazione e Addestramento | C6: =SUM(C7:C9) -> 9448 | D6: =C6/C24 -> 0.2472515
B7: Informazione/formazione dipendenti | C7: =C32*16 -> 8608 | E7: Costo di 16€ a dipendente annuo per formazione/informazione
B8: Formazione Dirigenti e Preposti | C8: =C31*300/C27 -> 720 | E8: Costo di 300€ a dirigente/preposto (12 in tutto) ogni 5 anni per formazione
B9: Formazione RLS/RSPP | C9: =300*C30/C27 -> 120 | E9: Costo di 300€ a RSPP/RLS (2 in tutto) ogni 5 anni per formazione
A10: Per la Sorveglianza sanitaria | C10: =SUM(C11:C12) -> 8380 | D10: =C10/C24 -> 0.21930224
B11: Medico competente e sorveglianza sanitaria | C11: 3000 | E11: Spesa fissa medico competente per sorveglianza
B12: Visite mediche | C12: =(C32/5*50) -> 5380 | E12: 50€ per visita dipendente per 1/5 dei dipendenti ogni anno
A13: Per la Gestione delle Emergenze | C13: =SUM(C14:C18) -> 1860 | D13: =C13/C24 -> 0.048675676
B14: Cassette di primo soccorso | C14: 500 | E14: Costo annuale di sostituzione del contenuto cassetta di primo soccorso
B15: Formazione personale addetto al primo soccorso | C15: =300*C28/C27 -> 480 | E15: Costo di 300€ ad addetto (8 in tutto) ogni 5 anni per formazione
B16: Manutenzione estintori | C16: 500 | E16: Canone annuo di manutenzione
B17: Manutenzione porte RAE | C17: 200 | E17: Canone annuo di manutenzione
B18: Formazione personale addetto alla prevenzione incendi | C18: =300*C29/C27 -> 180 | E18: Costo di 300€ ad addetto (3 in tutto) ogni 5 anni per formazione
A19: Per la pianificazione: redazione documenti | C19: =SUM(C20:C21) -> 3914.0216 | D19: =C19/C24 -> 0.10242884
B20: Redazione ed aggiornamento DVR | C20: =CCNL!I27*10 -> 1957.0108 | E20: 10 gg/u di un impiegato amministrativo al costo di un 5° livello € per gg/uu
B21: Redazione ed aggiornamento procedure e processi | C21: =CCNL!I27*10 -> 1957.0108 | E21: 10 gg/u di un impiegato amministrativo al costo di un 5° livello per gg/uu
A22: Spese amministrative varie | C22: =C23 -> 9000 | D22: =C22/C24 -> 0.23552747
B23: Adozione di modelli e sistemi di gestione della sicurezza (SA8000, ISO 45001,…) | C23: 9000 | E23: Quota di costi di certificazione per sicurezza sul lavoro
A24: Totale oneri della sicurezza aziendali | C24: =C3+C6+C10+C13+C19+C22 -> 38212.104
A25: Oneri della sicurezza per gg/uu | C25: =C26/220 -> 0.32284643
A26: Oneri della sicurezza per FTE | C26: =C24/C32 -> 71.026215
B27: PERIODO IN ANNI | C27: 5
B28: ADDETTI FORMAZIONE PRIMO SOCCORSO | C28: 8
B29: ADDETTI FORMAZIONE PREVENZIONE INCENDI | C29: 3
B30: NUMERO RLS/RSPP | C30: 2
A31: NUMERO DI DIRIGENTI | C31: 12
A32: NUMERO DI DIPENDENTI | C32: 538

Sheet ECONOMICA
A1: Prestazione | B1: Modalità | C1: Nr. | D1: Ricavo Unitario | E1: Ricavo Totale | G1: Canoni | H1: Servizi a corpo
A2: Application Maintenance | B2: Canone mensile | C2: 24 | D2: 0 | E2: =D2*C2 -> 0 | G2: =E3+E4+E6+E8 -> 34800 | H2: =E2+E5+E7+E9 -> 30620
A3: Implementazione nuove soluzioni - Manutenzione Evolutiva | B3: gg/u | C3: 800 | D3: 0 | E3: =D3*C3 -> 0
A4: Implementazione nuove soluzioni - Manutenzione Evolutiva (periodo opzionale) | B4: 0 | C4: 0 | D4: 0 | E4: =D4*C4 -> 0 | G4: =G2/20 -> 1740
A5: Manutenzione evolutiva | B5: gg/uu | C5: 66 | D5: 220 | E5: =D5*C5 -> 14520 | G5: Attivazione contratto 10-11-2025
A6: Hosting | B6: Canone mensile | C6: 24 | D6: 1200 | E6: =D6*C6 -> 28800 | G6: Durata Contratto 29 mesi (fino a 10-04-2028)
A7: Servizi specialistici: formazione | B7: A corpo | C7: 1 | D7: 2100 | E7: =D7*C7 -> 2100
A8: Servizi specialistici: assistenza operativa | B8: Canone mensile | C8: 24 | D8: 250 | E8: =D8*C8 -> 6000
A9: Servizi specialistici: altre componenti | B9: A corpo | C9: 1 | D9: 14000 | E9: =D9*C9 -> 14000
E10: =SUM(E2:E9) -> 65420

Sheet PROFILI PROFESSIONALI
A1: PROFILI PROFESSIONALI RICHIESTI — da Capitolato tecnico
A2: PROFILO | B2: N. RISORSE | C2: TITOLO DI STUDIO | D2: ESPERIENZA MINIMA | E2: CERTIFICAZIONI | F2: COMPETENZE | G2: CRITERIO PT | H2: PUNTEGGIO PT | I2: RUOLO TEAM | J2: LIVELLO CCNL | K2: COSTO GG CCNL | L2: COPERTO
A3: Capo Progetto | B3: 1 | C3: Laurea in discipline economiche o tecniche o cultura equivalente | D3: Almeno 10 anni di anzianità lavorativa, almeno 4 anni di provata esperienza nella specifica funzione su progetti complessi; almeno 2 anni di provata esperienza di analisi e progettazione nel settore assicurativo con periodi continuativi non inferiori a 6 mesi | F3: Metodologie di misura progetti e sviluppo, Agile, redazione specifiche, stima tempi e risorse, analisi processi, project management, Salesforce, Marketing Cloud, Sistemi ETL, Visualforce, Lightning component, APEX, Javascript, SOAP, REST, HTML/XML/CSS3/Javascript | I3: CAPO PROGETTO | J3: 8Q | K3: =IFERROR(_xludf.XLOOKUP(J3,CCNL!$C$3:$K$3,CCNL!$C$27:$K$27),"")
A4: Analista Senior | C4: Laurea in discipline economiche o tecniche o cultura equivalente | D4: Almeno 5 anni di anzianità lavorativa, almeno 2 anni di provata esperienza nella specifica funzione su progetti complessi; almeno 2 anni di provata esperienza nel settore assicurativo con periodi continuativi non inferiori a 6 mesi | F4: Programmazione e data modeling Force.com, web services d'integrazione, configurazione Salesforce, metodologie sviluppo, Agile, redazione specifiche, stima tempi e risorse, analisi processi, Salesforce, Marketing Cloud, Visualforce, Lightning component, APEX, Javascript, SOAP, REST, HTML/XML/CSS3/Javascript, Sistemi ETL
A5: Analista Programmatore | C5: Diploma e/o Laurea in discipline economiche o tecniche o cultura equivalente | D5: Almeno 2 anni di anzianità lavorativa, almeno 6 mesi di provata esperienza nella specifica funzione su progetti complessi; apprezzata conoscenza settore assicurativo | F5: Implementazione applicazioni custom su Lightning Salesforce, programmazione e manutenzione web services d'integrazione, configurazione Salesforce, redazione specifiche, analisi e progettazione sistemi, Salesforce, Marketing Cloud, Sistemi ETL, Visualforce, Lightning component, APEX, Javascript, SOAP, REST, HTML/XML/CSS3/Javascript
A6: Analista Programmatore Dati | C6: Laurea in discipline tecniche o Diploma perito informatico o equivalente (per non laureati esperienza lavorativa addizionale in ambito informatico) | D6: Almeno 6 anni di anzianità lavorativa, almeno 2 anni di provata esperienza di analisi e progettazione DWH e Business Intelligence; apprezzata conoscenza settore assicurativo | F6: Analisi, progettazione e implementazione flussi dati ETL, modellizzazione database, Quality Assurance dati, progettazione dashboard e reportistica Salesforce, estrazioni dati ad hoc, analisi funzionale/tecnica, Salesforce, Microsoft SQL Server, Integration Service, Reporting Service, Analysis Service, OLAP, Oracle, Visual Studio, Pentaho, strumenti gestione rilasci (TFS, Sonar, Jenkins)
A7: Specialista Digital Marketing | C7: Laurea in discipline tecniche o Diploma perito informatico o equivalente (per non laureati esperienza lavorativa addizionale in ambito informatico) | D7: Almeno 6 anni di anzianità lavorativa, almeno 2 anni di provata esperienza di analisi e progettazione marketing digitale; apprezzata conoscenza settore assicurativo | F7: Progettazione e gestione campagne email marketing, email automation, marketing automation, flussi email automation, piani editoriali, analisi performance campagne, Salesforce, Marketing Cloud, Visualforce, Lightning component, APEX, Javascript, SOAP, REST, HTML/XML/CSS3/Javascript, API, Google Analytics
A8: TOTALE | B8: =SUM(B3:B7) -> 1 | H8: =SUM(H3:H7) -> 0 | L8: =COUNTIF(L3:L7,"SÌ")&" / 5" -> 0 / 5

Sheet ALTRI REQUISITI
A1: ALTRI REQUISITI DI PARTECIPAZIONE — da Disciplinare di gara
A3: REQUISITI DI CAPACITÀ ECONOMICA E FINANZIARIA
A4: N. | B4: REQUISITO | C4: VALORE / SOGLIA | D4: RIFERIMENTO | E4: POSSEDUTO
A5: 1 | B5: Aver realizzato nei migliori tre anni degli ultimi cinque anni precedenti alla data di pubblicazione del Bando un fatturato globale (generale) non inferiore a Euro 1.390.400,00 IVA esclusa | C5: 1390400 | D5: § 14.2 | E5: NO
A7: REQUISITI DI IDONEITÀ PROFESSIONALE
A8: N. | B8: REQUISITO | C8: VALORE / SOGLIA | D8: RIFERIMENTO | E8: POSSEDUTO
A9: 1 | B9: Iscrizione nel registro della Camera di commercio, industria, artigianato e agricoltura o nel registro delle commissioni provinciali per l'artigianato o presso i competenti ordini professionali per attività pertinenti con quelle oggetto della presente procedura. Per operatori di altro Stato membro, iscrizione in uno dei registri professionali o commerciali degli altri Stati membri | D9: § 14.1, art. 100 comma 1 lett. a) e comma 3 Codice | E9: NO
A11: REQUISITI DI CAPACITÀ TECNICA E PROFESSIONALE
A12: N. | B12: REQUISITO | C12: VALORE / SOGLIA | D12: RIFERIMENTO | E12: POSSEDUTO
A13: 1 | B13: Aver eseguito negli ultimi 10 anni antecedenti la data di pubblicazione del bando di gara, in favore di Pubbliche Amministrazioni e/o soggetti privati, almeno 3 contratti del valore complessivo non inferiore a Euro 695.200,00 IVA esclusa, aventi ad oggetto servizi analoghi a quelli richiesti dalla presente procedura di gara | C13: 695200 | D13: § 14.3 | E13: NO
A15: POSSEDUTI | B15: =COUNTIF(E1:E14,"SÌ")&" / "&(COUNTIF(E1:E14,"SÌ")+COUNTIF(E1:E14,"NO")) -> 0 / 3

Sheet OGGETTO FORNITURA E SERVIZI
A1: OGGETTO DELLA FORNITURA E SERVIZI — da Capitolato tecnico
A2: DURATA BASE (MESI) | B2: 24 | C2: DURATA OPZIONE (MESI) | D2: 24 | E2: GG/ANNO PER FTE | F2: =CCNL!$B$41 -> 215.875
A4: TIPOLOGIA DI SERVIZIO | B4: SERVIZIO | C4: AMBITO | D4: FIGURA PROFESSIONALE | E4: % UTILIZZO MIN | F4: % UTILIZZO MAX | G4: % MEDIA | H4: FTE / ANNO | I4: GG/U PERIODO BASE | J4: GG/U OPZIONE | K4: GG/U TOTALI | L4: DESCRIZIONE
A5: Application Maintenance | H5: 2 | I5: =H5*$F$2*$B$2/12 -> 863.5 | J5: =H5*$F$2*$D$2/12 -> 863.5 | K5: =IF(COUNT(I5:J5),SUM(I5:J5),"") -> 1727 | L5: Servizio di manutenzione correttiva, supporto di 2° livello sistemistico, piccola manutenzione evolutiva e gestione dati su framework Salesforce
C6: Manutenzione Correttiva | L6: Problem determination e problem solving per malfunzionamenti applicazioni, adeguamenti per upgrade versioni, upgrade periodici Salesforce, adeguamenti per cambiamenti condizioni al contorno, modifiche al sistema dati e configurazioni
D7: Analista Senior | E7: 0.35 | F7: 0.5 | G7: =IF(COUNT(E7:F7),AVERAGE(E7:F7),"") -> 0.425 | I7: =IF(G7<>"",G7*I$5,"") -> 366.9875 | J7: =IF(G7<>"",G7*J$5,"") -> 366.9875 | K7: =IF(COUNT(I7:J7),SUM(I7:J7),"") -> 733.975
D8: Analista Programmatore | E8: 0.5 | F8: 0.65 | G8: =IF(COUNT(E8:F8),AVERAGE(E8:F8),"") -> 0.575 | I8: =IF(G8<>"",G8*I$5,"") -> 496.5125 | J8: =IF(G8<>"",G8*J$5,"") -> 496.5125 | K8: =IF(COUNT(I8:J8),SUM(I8:J8),"") -> 993.025
C9: Supporto di 2° Livello Sistemistico e Administrator | L9: Supporto applicativo di 2° livello, supporto sistemistico e administrator, malfunzionamenti da errori software, problemi da utilizzo errato, supporto funzionalità tecniche, supporto infrastrutturale, gestione anagrafica e profili utenti, gestione campagne marketing cloud
D10: Analista Senior | E10: 0.35 | F10: 0.5 | G10: =IF(COUNT(E10:F10),AVERAGE(E10:F10),"") -> 0.425 | I10: =IF(G10<>"",G10*I$5,"") -> 366.9875 | J10: =IF(G10<>"",G10*J$5,"") -> 366.9875 | K10: =IF(COUNT(I10:J10),SUM(I10:J10),"") -> 733.975
D11: Analista Programmatore | E11: 0.5 | F11: 0.65 | G11: =IF(COUNT(E11:F11),AVERAGE(E11:F11),"") -> 0.575 | I11: =IF(G11<>"",G11*I$5,"") -> 496.5125 | J11: =IF(G11<>"",G11*J$5,"") -> 496.5125 | K11: =IF(COUNT(I11:J11),SUM(I11:J11),"") -> 993.025
C12: Piccola Manutenzione Evolutiva | L12: Interventi di modesta entità (Effort <= 5 gg/u) per modifiche funzionalità esistenti, sviluppo nuove funzionalità, parametrizzazione per nuove esigenze, manutenzione evolutiva reportistica ed estrazione dati
D13: Analista Senior | E13: 0.35 | F13: 0.5 | G13: =IF(COUNT(E13:F13),AVERAGE(E13:F13),"") -> 0.425 | I13: =IF(G13<>"",G13*I$5,"") -> 366.9875 | J13: =IF(G13<>"",G13*J$5,"") -> 366.9875 | K13: =IF(COUNT(I13:J13),SUM(I13:J13),"") -> 733.975
D14: Analista Programmatore | E14: 0.5 | F14: 0.65 | G14: =IF(COUNT(E14:F14),AVERAGE(E14:F14),"") -> 0.575 | I14: =IF(G14<>"",G14*I$5,"") -> 496.5125 | J14: =IF(G14<>"",G14*J$5,"") -> 496.5125 | K14: =IF(COUNT(I14:J14),SUM(I14:J14),"") -> 993.025
D15: Analista Programmatore Dati | G15: =IF(COUNT(E15:F15),AVERAGE(E15:F15),"") | I15: =IF(G15<>"",G15*I$5,"") | J15: =IF(G15<>"",G15*J$5,"") | K15: =IF(COUNT(I15:J15),SUM(I15:J15),"")
A16: Implementazione di Nuove Soluzioni | I16: 800 | J16: 800 | K16: =IF(COUNT(I16:J16),SUM(I16:J16),"") -> 1600 | L16: Realizzazione di funzionalità non esistenti, inserimento nuove funzionalità, modifica funzioni in esercizio, parametrizzazione e personalizzazione piattaforma Salesforce, realizzazione web services d'integrazione
C17: Analisi e Definizione | L17: Identificazione esigenze di sviluppo, definizione ipotesi di soluzione, pianificazione realizzazione, valutazione d'impatto, stima giorni uomo e costi
D18: Capo Progetto | G18: =IF(COUNT(E18:F18),AVERAGE(E18:F18),"") | I18: =IF(G18<>"",G18*I$16,"") | J18: =IF(G18<>"",G18*J$16,"") | K18: =IF(COUNT(I18:J18),SUM(I18:J18),"")
D19: Analista Senior | E19: 0.3 | F19: 0.5 | G19: =IF(COUNT(E19:F19),AVERAGE(E19:F19),"") -> 0.4 | I19: =IF(G19<>"",G19*I$16,"") -> 320 | J19: =IF(G19<>"",G19*J$16,"") -> 320 | K19: =IF(COUNT(I19:J19),SUM(I19:J19),"") -> 640
C20: Realizzazione | L20: Implementazione componenti software, realizzazione web services, esecuzione test, creazione documentazione, consegna componenti
D21: Analista Programmatore | E21: 0.35 | F21: 0.55 | G21: =IF(COUNT(E21:F21),AVERAGE(E21:F21),"") -> 0.45 | I21: =IF(G21<>"",G21*I$16,"") -> 360 | J21: =IF(G21<>"",G21*J$16,"") -> 360 | K21: =IF(COUNT(I21:J21),SUM(I21:J21),"") -> 720
D22: Analista Programmatore Dati | E22: 0.15 | F22: 0.35 | G22: =IF(COUNT(E22:F22),AVERAGE(E22:F22),"") -> 0.25 | I22: =IF(G22<>"",G22*I$16,"") -> 200 | J22: =IF(G22<>"",G22*J$16,"") -> 200 | K22: =IF(COUNT(I22:J22),SUM(I22:J22),"") -> 400
C23: Collaudo e Validazione | L23: Supporto predisposizione ambiente collaudo, installazione prodotti sviluppati, supporto esecuzione collaudo, supporto passaggio in produzione
D24: Analista Programmatore | E24: 0.35 | F24: 0.55 | G24: =IF(COUNT(E24:F24),AVERAGE(E24:F24),"") -> 0.45 | I24: =IF(G24<>"",G24*I$16,"") -> 360 | J24: =IF(G24<>"",G24*J$16,"") -> 360 | K24: =IF(COUNT(I24:J24),SUM(I24:J24),"") -> 720
D25: Analista Senior | E25: 0.3 | F25: 0.5 | G25: =IF(COUNT(E25:F25),AVERAGE(E25:F25),"") -> 0.4 | I25: =IF(G25<>"",G25*I$16,"") -> 320 | J25: =IF(G25<>"",G25*J$16,"") -> 320 | K25: =IF(COUNT(I25:J25),SUM(I25:J25),"") -> 640
C26: Manutenzione Evolutiva Reportistica ed Estrazione Dati | L26: Realizzazione nuovi report/query, modifica report esistenti, procedure alimentazione basi dati, estrazione dati propedeutici a studi/analisi, bonifiche e initial load
D27: Analista Programmatore Dati | E27: 0.15 | F27: 0.35 | G27: =IF(COUNT(E27:F27),AVERAGE(E27:F27),"") -> 0.25 | I27: =IF(G27<>"",G27*I$16,"") -> 200 | J27: =IF(G27<>"",G27*J$16,"") -> 200 | K27: =IF(COUNT(I27:J27),SUM(I27:J27),"") -> 400
A29: TOTALE | I29: =SUM(I5,I16) -> 1663.5 | J29: =SUM(J5,J16) -> 1663.5 | K29: =SUM(K5,K16) -> 3327

Sheet DICHIARAZIONE OFFERTA ECONOMICA
A1: DICHIARAZIONE OFFERTA ECONOMICA — collegamento con il foglio ECONOMICA
A3: CODICE | B3: VOCE DICHIARAZIONE | C3: UNITÀ | D3: Q.TÀ DICHIARATA | E3: RIGA ECONOMICA | F3: PRESTAZIONE ECONOMICA | G3: Q.TÀ ECONOMICA | H3: PREZZO UNITARIO | I3: TOTALE | J3: COERENZA | K3: CRITERIO PT | L3: NOTE
A4: 1 | B4: Servizio di Application Maintenance - Canone mensile | C4: mese | D4: 24 | E4: 2 | F4: =ECONOMICA!A2 -> Application Maintenance | G4: =ECONOMICA!C2 -> 24 | H4: =ECONOMICA!D2 -> 0 | I4: =IF(AND(ISNUMBER(G4),ISNUMBER(H4)),G4*H4,"") -> 0 | J4: =IF(D4="","—",IF(D4=G4,"OK","VERIFICARE")) -> OK | L4: Importo base d'asta: Euro 695.200 per 24 mesi, IVA esclusa
A5: 1.1 | B5: Analista Funzionale (analista senior) - Application Maintenance | J5: ELEMENTO TECNICO | L5: Mix percentuale da compilare
A6: 1.2 | B6: Analista Programmatore - Application Maintenance | D6: 100 | J6: ELEMENTO TECNICO | L6: Mix percentuale: 100%
A7: 2 | B7: Servizio di Implementazione nuove soluzioni - Tariffa media giornaliera | C7: gg/u | D7: 800 | E7: 3 | F7: =ECONOMICA!A3 -> Implementazione nuove soluzioni - Manutenzione Evolutiva | G7: =ECONOMICA!C3 -> 800 | H7: =ECONOMICA!D3 -> 0 | I7: =IF(AND(ISNUMBER(G7),ISNUMBER(H7)),G7*H7,"") -> 0 | J7: =IF(D7="","—",IF(D7=G7,"OK","VERIFICARE")) -> OK | L7: 800 giornate uomo stimate
A8: 2.1 | B8: Analista Funzionale - Implementazione nuove soluzioni | C8: Euro/giorno | E8: 3 | F8: =ECONOMICA!A3 -> Implementazione nuove soluzioni - Manutenzione Evolutiva | G8: =ECONOMICA!C3 -> 800 | H8: =ECONOMICA!D3 -> 0 | I8: =IF(AND(ISNUMBER(G8),ISNUMBER(H8)),G8*H8,"") -> 0 | J8: =IF(D8="","—",IF(D8=G8,"OK","VERIFICARE")) -> — | L8: Tariffa unitaria giornaliera da compilare, Mix percentuale da compilare
A9: 2.2 | B9: Analista Programmatore - Implementazione nuove soluzioni | C9: Euro/giorno | E9: 3 | F9: =ECONOMICA!A3 -> Implementazione nuove soluzioni - Manutenzione Evolutiva | G9: =ECONOMICA!C3 -> 800 | H9: =ECONOMICA!D3 -> 0 | I9: =IF(AND(ISNUMBER(G9),ISNUMBER(H9)),G9*H9,"") -> 0 | J9: =IF(D9="","—",IF(D9=G9,"OK","VERIFICARE")) -> — | L9: Tariffa unitaria giornaliera da compilare, Mix percentuale da compilare
A10: 2.3 | B10: Analista Programmatore dati - Implementazione nuove soluzioni | C10: Euro/giorno | D10: 100 | E10: 3 | F10: =ECONOMICA!A3 -> Implementazione nuove soluzioni - Manutenzione Evolutiva | G10: =ECONOMICA!C3 -> 800 | H10: =ECONOMICA!D3 -> 0 | I10: =IF(AND(ISNUMBER(G10),ISNUMBER(H10)),G10*H10,"") -> 0 | J10: =IF(D10="","—",IF(D10=G10,"OK","VERIFICARE")) -> VERIFICARE | L10: Tariffa unitaria giornaliera da compilare, Mix percentuale: 100%
B11: Percentuale di ribasso sull'importo a base d'asta | C11: % | J11: NON COLLEGATA | L11: Da compilare in cifre e lettere
B12: Costi aziendali per salute e sicurezza sui luoghi di lavoro (art. 108, comma 9 D.Lgs. 36/2023) | C12: Euro | J12: ELEMENTO TECNICO | L12: Da compilare
B13: Costi della manodopera | C13: Euro | J13: ELEMENTO TECNICO | L13: Da compilare
A14: TOTALE COLLEGATO | I14: =SUM(I4:I13) -> 0 | J14: =COUNTIF(J4:J13,"OK")&" / 10 coerenti" -> 2 / 10 coerenti
A16: DICHIARAZIONI E IMPEGNI
